<?xml version="1.0" ?>
<!-- =================================================================================== -->
<!-- |    This document was autogenerated by xacro from vx300s.urdf.xacro              | -->
<!-- |    EDITING THIS FILE BY HAND IS NOT RECOMMENDED                                 | -->
<!-- =================================================================================== -->
<robot name="aloha">
  <!-- <material name="interbotix_black">
    <texture filename="meshes/interbotix_black.png"/>
  </material> -->
  <link name="table">
    <visual>
      <origin xyz="0 0 0"/>
      <geometry>
        <mesh filename="meshes/table.obj" scale="1 1 1"/>
      </geometry>
    </visual>
    <collision>
      <origin xyz="0 0 0"/>
      <geometry>
        <box size="0.8 1.2 0.01"/>
      </geometry>
    </collision>
  </link>

 <!-- ++++++++++++++++++++++++++++++++++++++++++left robot start +++++++++++++++++++++++++++++++++++++++++++ -->
  <joint name="left/base_joint" type="fixed">
    <axis xyz="0 0 1"/>
    <origin rpy="0 0 1.57" xyz="-0.005 -0.525 0.02"/> 
    <parent link="table"/>
    <child link="left/vx300s/base_link"/>
    <dynamics friction="0.1"/>
  </joint>
  <link name="left/vx300s/base_link">
    <visual>
      <origin rpy="0 0 1.5707963267948966" xyz="0 0 0"/>
      <geometry>
        <mesh filename="meshes/vx300s_meshes/vx300s_1_base.stl" scale="0.001 0.001 0.001"/>
      </geometry>
      <material name="interbotix_black"/>
    </visual>
    <collision>
      <origin rpy="0 0 1.5707963267948966" xyz="0 0 0"/>
      <geometry>
        <mesh filename="meshes/vx300s_meshes/vx300s_1_base.stl" scale="0.001 0.001 0.001"/>
      </geometry>
    </collision>
    <inertial>
      <origin rpy="0 0 1.5707963267948966" xyz="-0.0534774000 -0.0005625750 0.0205961000"/>
      <mass value="0.969034"/>
      <inertia ixx="0.0060240000" ixy="0.0000471300" ixz="0.0000038510" iyy="0.0017000000" iyz="-0.0000841500" izz="0.0071620000"/>
    </inertial>
  </link>
  <joint name="left/waist" type="revolute">
    <axis xyz="0 0 1"/>
    <limit effort="10" lower="-3.141582653589793" upper="3.141582653589793" velocity="3.141592653589793"/>
    <origin rpy="0 0 0" xyz="0 0 0.079"/>
    <parent link="left/vx300s/base_link"/>
    <child link="left/vx300s/shoulder_link"/>
    <dynamics friction="0.1"/>
  </joint>

  <link name="left/vx300s/shoulder_link">
    <visual>
      <origin rpy="0 0 1.5707963267948966" xyz="0 0 -0.003"/>
      <geometry>
        <mesh filename="meshes/vx300s_meshes/vx300s_2_shoulder.stl" scale="0.001 0.001 0.001"/>
      </geometry>
      <material name="interbotix_black"/>
    </visual>
    <collision>
      <origin rpy="0 0 1.5707963267948966" xyz="0 0 -0.003"/>
      <geometry>
        <mesh filename="meshes/vx300s_meshes/vx300s_2_shoulder.stl" scale="0.001 0.001 0.001"/>
      </geometry>
    </collision>
    <inertial>
      <origin rpy="0 0 1.5707963267948966" xyz="0.0002592330 -0.0000033552 0.0116129000"/>
      <mass value="0.798614"/>
      <inertia ixx="0.0009388000" ixy="-0.0000000010" ixz="-0.0000000191" iyy="0.0011380000" iyz="0.0000059568" izz="0.0012010000"/>
    </inertial>
  </link>
  <joint name="left/shoulder" type="revolute">
    <axis xyz="0 1 0"/>
    <limit effort="20" lower="-1.8500490071139892" upper="1.2566370614359172" velocity="3.141592653589793"/>
    <origin rpy="0 0 0" xyz="0 0 0.04805"/>
    <parent link="left/vx300s/shoulder_link"/>
    <child link="left/vx300s/upper_arm_link"/>
    <dynamics friction="0.1"/>
  </joint>

  <link name="left/vx300s/upper_arm_link">
    <visual>
      <origin rpy="0 0 1.5707963267948966" xyz="0 0 0"/>
      <geometry>
        <mesh filename="meshes/vx300s_meshes/vx300s_3_upper_arm.stl" scale="0.001 0.001 0.001"/>
      </geometry>
      <material name="interbotix_black"/>
    </visual>
    <collision>
      <origin rpy="0 0 1.5707963267948966" xyz="0 0 0"/>
      <geometry>
        <mesh filename="meshes/vx300s_meshes/vx300s_3_upper_arm.stl" scale="0.001 0.001 0.001"/>
      </geometry>
    </collision>
    <inertial>
      <origin rpy="0 0 1.5707963267948966" xyz="0.0206949000 0.0000000004 0.2264590000"/>
      <mass value="0.792592"/>
      <inertia ixx="0.0089250000" ixy="0.0000000000" ixz="0.0000000000" iyy="0.0089370000" iyz="0.0012010000" izz="0.0009357000"/>
    </inertial>
  </link>
  <joint name="left/elbow" type="revolute">
    <axis xyz="0 1 0"/>
    <limit effort="15" lower="-1.7627825445142729" upper="1.6057029118347832" velocity="3.141592653589793"/>
    <origin rpy="0 0 0" xyz="0.05955 0 0.3"/>
    <parent link="left/vx300s/upper_arm_link"/>
    <child link="left/vx300s/upper_forearm_link"/>
    <dynamics friction="0.1"/>
  </joint>

  <link name="left/vx300s/upper_forearm_link">
    <visual>
      <origin rpy="0 0 0" xyz="0 0 0"/>
      <geometry>
        <mesh filename="meshes/vx300s_meshes/vx300s_4_upper_forearm.stl" scale="0.001 0.001 0.001"/>
      </geometry>
      <material name="interbotix_black"/>
    </visual>
    <collision>
      <origin rpy="0 0 0" xyz="0 0 0"/>
      <geometry>
        <mesh filename="meshes/vx300s_meshes/vx300s_4_upper_forearm.stl" scale="0.001 0.001 0.001"/>
      </geometry>
    </collision>
    <inertial>
      <origin rpy="0 0 0" xyz="0.10723 0 0"/>
      <mass value="0.322228"/>
      <inertia ixx="0.0001524000" ixy="-0.0000188300" ixz="-0.0000084064" iyy="0.0013420000" iyz="0.0000012564" izz="0.0014410000"/>
    </inertial>
  </link>
  <joint name="left/forearm_roll" type="revolute">
    <axis xyz="1 0 0"/>
    <limit effort="2" lower="-3.141582653589793" upper="3.141582653589793" velocity="3.141592653589793"/>
    <origin rpy="0 0 0" xyz="0.2 0 0"/>
    <parent link="left/vx300s/upper_forearm_link"/>
    <child link="left/vx300s/lower_forearm_link"/>
    <dynamics friction="0.1"/>
  </joint>

  <link name="left/vx300s/lower_forearm_link">
    <visual>
      <origin rpy="3.141592653589793 0 0" xyz="0 0 0"/>
      <geometry>
        <mesh filename="meshes/vx300s_meshes/vx300s_5_lower_forearm.stl" scale="0.001 0.001 0.001"/>
      </geometry>
      <material name="interbotix_black"/>
    </visual>
    <collision>
      <origin rpy="3.141592653589793 0 0" xyz="0 0 0"/>
      <geometry>
        <mesh filename="meshes/vx300s_meshes/vx300s_5_lower_forearm.stl" scale="0.001 0.001 0.001"/>
      </geometry>
    </collision>
    <inertial>
      <origin rpy="3.141592653589793 0 0" xyz="0.0513477000 0.0068046200 0"/>
      <mass value="0.214823"/>
      <inertia ixx="0.0001753000" ixy="-0.0000852800" ixz="0" iyy="0.0005269000" iyz="0" izz="0.0005911000"/>
    </inertial>
  </link>
  <joint name="left/wrist_angle" type="revolute">
    <axis xyz="0 1 0"/>
    <limit effort="5" lower="-1.8675022996339325" upper="2.234021442552742" velocity="3.141592653589793"/>
    <origin rpy="0 0.05 0" xyz="0.1 0 0"/>
    <parent link="left/vx300s/lower_forearm_link"/>
    <child link="left/vx300s/wrist_link"/>
    <dynamics friction="0.1"/>
  </joint>

  <link name="left/vx300s/wrist_link">
    <visual>
      <origin rpy="0 0 1.5707963267948966" xyz="0 0 0"/>
      <geometry>
        <mesh filename="meshes/vx300s_meshes/vx300s_6_wrist.stl" scale="0.001 0.001 0.001"/>
      </geometry>
      <material name="interbotix_black"/>
    </visual>
    <collision>
      <origin rpy="0 0 1.5707963267948966" xyz="0 0 0"/>
      <geometry>
        <mesh filename="meshes/vx300s_meshes/vx300s_6_wrist.stl" scale="0.001 0.001 0.001"/>
      </geometry>
    </collision>
    <inertial>
      <origin rpy="0 0 1.5707963267948966" xyz="0.0467430000 -0.0000076652 0.0105650000"/>
      <mass value="0.115395"/>
      <inertia ixx="0.0000463100" ixy="0.0000000195" ixz="0.0000000023" iyy="0.0000451400" iyz="0.0000042002" izz="0.0000527000"/>
    </inertial>
  </link>
  <joint name="left/wrist_rotate" type="revolute">
    <axis xyz="1 0 0"/>
    <limit effort="1" lower="-3.141582653589793" upper="3.141582653589793" velocity="3.141592653589793"/>
    <origin rpy="0 0 0" xyz="0.069744 0 0"/>
    <parent link="left/vx300s/wrist_link"/>
    <child link="left/vx300s/gripper_link"/>
    <dynamics friction="0.1"/>
  </joint>

  <link name="left/vx300s/gripper_link">
    <visual>
      <origin rpy="0 0 1.5707963267948966" xyz="-0.02 0 0"/>
      <geometry>
        <mesh filename="meshes/vx300s_meshes/vx300s_7_gripper.stl" scale="0.001 0.001 0.001"/>
      </geometry>
      <material name="interbotix_black"/>
    </visual>
    <collision>
      <origin rpy="0 0 1.5707963267948966" xyz="-0.02 0 0"/>
      <geometry>
        <mesh filename="meshes/vx300s_meshes/vx300s_7_gripper.stl" scale="0.001 0.001 0.001"/>
      </geometry>
    </collision>
    <inertial>
      <origin rpy="0 0 1.5707963267948966" xyz="0.0230010000 0.0000000000 0.0115230000"/>
      <mass value="0.097666"/>
      <inertia ixx="0.0000326800" ixy="0.0000000000" ixz="0.0000000000" iyy="0.0000243600" iyz="0.0000002785" izz="0.0000211900"/>
    </inertial>
  </link>
  <joint name="left/ee_arm" type="fixed">
    <axis xyz="1 0 0"/>
    <origin rpy="0 0 0" xyz="0.042825 0 0"/>
    <parent link="left/vx300s/gripper_link"/>
    <child link="left/vx300s/ee_arm_link"/>
  </joint>
  <link name="left/vx300s/ee_arm_link">
    <inertial>
      <mass value="0.001"/>
      <inertia ixx="0.0001" ixy="0" ixz="0" iyy="0.0001" iyz="0" izz="0.0001"/>
    </inertial>
  </link>
  <joint name="left/gripper" type="fixed">
    <axis xyz="1 0 0"/>
    <limit effort="1" velocity="3.141592653589793"/>
    <origin rpy="0 0 0" xyz="0.005675 0 0"/>
    <parent link="left/vx300s/ee_arm_link"/>
    <child link="left/vx300s/gripper_prop_link"/>
    <dynamics friction="0.1"/>
  </joint>

  <link name="left/vx300s/gripper_prop_link">
    <visual>
      <origin rpy="0 0 1.5707963267948966" xyz="-0.0685 0 0"/>
      <geometry>
        <mesh filename="meshes/vx300s_meshes/vx300s_8_gripper_prop.stl" scale="0.001 0.001 0.001"/>
      </geometry>
      <material name="interbotix_black"/>
    </visual>
    <collision>
      <origin rpy="0 0 1.5707963267948966" xyz="-0.0685 0 0"/>
      <geometry>
        <mesh filename="meshes/vx300s_meshes/vx300s_8_gripper_prop.stl" scale="0.001 0.001 0.001"/>
      </geometry>
    </collision>
    <inertial>
      <origin rpy="0 0 1.5707963267948966" xyz="0.0023780000 0.0000000285 0.0000000000"/>
      <mass value="0.008009"/>
      <inertia ixx="0.0000020386" ixy="0.0000000000" ixz="0.0000006559" iyy="0.0000042979" iyz="0.0000000000" izz="0.0000023796"/>
    </inertial>
  </link>
  <!-- If the AR tag is being used, then add the AR tag mount -->
  <!-- If the gripper bar is being used, then also add the gripper bar -->
  <joint name="left/gripper_bar" type="fixed">
    <axis xyz="1 0 0"/>
    <origin rpy="0 0 0" xyz="0 0 0"/>
    <parent link="left/vx300s/ee_arm_link"/>
    <child link="left/vx300s/gripper_bar_link"/>
  </joint>
  <link name="left/vx300s/gripper_bar_link">
    <visual>
      <origin rpy="1.57 0 1.57" xyz="0 0 0"/>
      <geometry>
        <mesh filename="meshes/vx300s_meshes/vx300s_9_gripper_bar.stl" scale="1 1 1"/>
      </geometry>
      <material name="interbotix_black"/>
    </visual>
    <collision>
      <origin rpy="1.57 0 1.57" xyz="0 0 0"/>
      <geometry>
        <mesh filename="meshes/vx300s_meshes/vx300s_9_gripper_bar.stl" scale="0.001 0.001 0.001"/>
      </geometry>
    </collision>
    <inertial>
      <origin rpy="1.57 0 1.57" xyz="0.0067940000 -0.0000004272 -0.0007760000"/>
      <mass value="0.150986"/>
      <inertia ixx="0.0000789500" ixy="-0.0000000012" ixz="0.0000001341" iyy="0.0003283000" iyz="0.0000017465" izz="0.0003095000"/>
    </inertial>
  </link>
  <joint name="left/ee_bar" type="fixed">
    <axis xyz="1 0 0"/>
    <origin rpy="0 0 0" xyz="0.025875 0 0"/>
    <parent link="left/vx300s/gripper_bar_link"/>
    <child link="left/vx300s/fingers_link"/>
  </joint>
  <link name="left/vx300s/fingers_link">
    <inertial>
      <mass value="0.001"/>
      <inertia ixx="0.0001" ixy="0" ixz="0" iyy="0.0001" iyz="0" izz="0.0001"/>
    </inertial>
  </link>
  <!-- If the gripper fingers are being used, add those as well -->
  <joint name="left/left_finger" type="prismatic">
    <axis xyz="0 1 0"/>
    <limit effort="5" lower="0.0" upper="0.042" velocity="1"/>
    <origin rpy="0 0 0" xyz="0 0 0"/>
    <parent link="left/vx300s/fingers_link"/>
    <child link="left/vx300s/left_finger_link"/>
    <dynamics friction="0.1"/>
  </joint>

  <link name="left/vx300s/left_finger_link">
    <visual>
      <origin rpy="0 0 1.57 " xyz="0.135 -0.000 0.0125"/>
      <geometry>
        <mesh filename="meshes/vx300s_meshes/gripper.obj" scale="0.001 0.001 0.001"/>
      </geometry>
    </visual>
    <collision>
      <origin rpy="0 0 1.57 " xyz="0.135 -0.000 0.0125"/>
      <geometry>
        <mesh filename="meshes/vx300s_meshes/gripper.obj" scale="0.001 0.001 0.001"/>
      </geometry>
    </collision>
    <inertial>
      <origin rpy="0 0 1.57 " xyz="0.135 -0.000 0.0125"/>
      <mass value="0.034796"/>
      <inertia ixx="0.0000243300" ixy="-0.0000024004" ixz="0.0000000000" iyy="0.0000125500" iyz="0.0000000000" izz="0.0000141700"/>
    </inertial>
  </link>

  <joint name="left_arm_elastomer_joint_left" type="fixed">
      <origin rpy="0 -1.57 0" xyz="0.10 0.0012 -0.00"/>
      <parent link="left/vx300s/left_finger_link"/>
      <child link="left_arm_elastomer_left"/>
      <axis xyz="0 0 0"/>
  </joint>
  <link name="left_arm_elastomer_left">         <!-- surface tip of the elastomer  -->
      <visual>
          <origin rpy="0 0 0" xyz="0 0 -0.00"/>     <!-- needed when flipping visual mesh in IG  -->
          <geometry>
              <mesh filename="./meshes/aloha_flat_pad.obj"/>
          </geometry>
          <material name="black">
            <color rgba="0.0 0.0 0.0 1.0"/>
          </material>
      </visual>
      <collision>
        <origin rpy="0 0 0" xyz="0 0 -0.00"/> 
          <geometry>
              <mesh filename="./meshes/aloha_flat_pad.obj"/>
          </geometry>
          <!-- <sdf resolution="256"/> -->
      </collision>
  </link>

  <joint name="left/right_finger" type="prismatic">
    <axis xyz="0 1 0"/>
    <limit effort="5" lower="-0.042" upper="-0.00" velocity="1"/>
    <origin rpy="0 0 0" xyz="0 0 0"/>
    <parent link="left/vx300s/fingers_link"/>
    <child link="left/vx300s/right_finger_link"/>
    <dynamics friction="0.1"/>
    <!-- <mimic joint="left_finger" multiplier="-1" offset="0"/> -->
  </joint>

  <link name="left/vx300s/right_finger_link">
    <visual>
      <origin rpy="3.14 0 -1.57 " xyz="0.135 0.000 -0.0125"/>
      <geometry>
        <mesh filename="meshes/vx300s_meshes/gripper.obj" scale="0.001 0.001 0.001"/>
      </geometry>
    </visual>
    <collision>
      <origin rpy="3.14 0 -1.57 " xyz="0.135 0.000 -0.0125"/>
      <geometry>
        <mesh filename="meshes/vx300s_meshes/gripper.obj" scale="0.001 0.001 0.001"/>
      </geometry>
    </collision>
    <inertial>
      <origin rpy="3.14 0 -1.57 " xyz="0.135 0.000 -0.0125"/>
      <mass value="0.034796"/>
      <inertia ixx="0.0000243300" ixy="0.0000024001" ixz="0.0000000000" iyy="0.0000125500" iyz="0.0000000000" izz="0.0000141700"/>
    </inertial>
  </link>

  <joint name="left_arm_elastomer_joint_right" type="fixed">
      <origin rpy="3.14 1.57 0" xyz="0.10 -0.0012 -0.00"/>
      <parent link="left/vx300s/right_finger_link"/>
      <child link="left_arm_elastomer_right"/>
      <axis xyz="0 0 0"/>
  </joint>
  <link name="left_arm_elastomer_right">         <!-- surface tip of the elastomer  -->
      <visual>
          <origin rpy="0 0 0" xyz="0 0 -0.00"/>     <!-- needed when flipping visual mesh in IG  -->
          <geometry>
              <mesh filename="./meshes/aloha_flat_pad.obj"/>
          </geometry>
          <material name="black">
            <color rgba="0.0 0.0 0.0 1.0"/>
          </material>
      </visual>
      <collision>
        <origin rpy="0 0 0" xyz="0 0 -0.00"/> 
          <geometry>
              <mesh filename="./meshes/aloha_flat_pad.obj"/>
          </geometry>
          <!-- <sdf resolution="256"/> -->
      </collision>
  </link>
  
  <joint name="left/ee_gripper" type="fixed">
    <axis xyz="1 0 0"/>
    <origin rpy="0 0 0" xyz="0.0385 0 0"/>
    <parent link="left/vx300s/fingers_link"/>
    <child link="left/vx300s/ee_gripper_link"/>
  </joint>
  <link name="left/vx300s/ee_gripper_link">
    <inertial>
      <mass value="0.001"/>
      <inertia ixx="0.0001" ixy="0" ixz="0" iyy="0.0001" iyz="0" izz="0.0001"/>
    </inertial>
  </link>

 <!-- ++++++++++++++++++++++++++++++++++++++++++left robot end +++++++++++++++++++++++++++++++++++++++++++ -->


 <!-- ++++++++++++++++++++++++++++++++++++++++++right robot start +++++++++++++++++++++++++++++++++++++++++++ -->

  <joint name="right/base_joint" type="fixed">
    <axis xyz="0 0 1"/>
    <origin rpy="0 0 -1.57" xyz="0.005 0.525 0.02"/>
    <parent link="table"/>
    <child link="right/vx300s/base_link"/>
    <dynamics friction="0.1"/>
  </joint>

  <link name="right/vx300s/base_link">
    <visual>
      <origin rpy="0 0 1.5707963267948966" xyz="0 0 0"/>
      <geometry>
        <mesh filename="meshes/vx300s_meshes/vx300s_1_base.stl" scale="0.001 0.001 0.001"/>
      </geometry>
      <material name="interbotix_black"/>
    </visual>
    <collision>
      <origin rpy="0 0 1.5707963267948966" xyz="0 0 0"/>
      <geometry>
        <mesh filename="meshes/vx300s_meshes/vx300s_1_base.stl" scale="0.001 0.001 0.001"/>
      </geometry>
    </collision>
    <inertial>
      <origin rpy="0 0 1.5707963267948966" xyz="-0.0534774000 -0.0005625750 0.0205961000"/>
      <mass value="0.969034"/>
      <inertia ixx="0.0060240000" ixy="0.0000471300" ixz="0.0000038510" iyy="0.0017000000" iyz="-0.0000841500" izz="0.0071620000"/>
    </inertial>
  </link>

  <joint name="right/waist" type="revolute">
    <axis xyz="0 0 1"/>
    <limit effort="10" lower="-3.141582653589793" upper="3.141582653589793" velocity="3.141592653589793"/>
    <origin rpy="0 0 0" xyz="0 0 0.079"/>
    <parent link="right/vx300s/base_link"/>
    <child link="right/vx300s/shoulder_link"/>
    <dynamics friction="0.1"/>
  </joint>

  <link name="right/vx300s/shoulder_link">
    <visual>
      <origin rpy="0 0 1.5707963267948966" xyz="0 0 -0.003"/>
      <geometry>
        <mesh filename="meshes/vx300s_meshes/vx300s_2_shoulder.stl" scale="0.001 0.001 0.001"/>
      </geometry>
      <material name="interbotix_black"/>
    </visual>
    <collision>
      <origin rpy="0 0 1.5707963267948966" xyz="0 0 -0.003"/>
      <geometry>
        <mesh filename="meshes/vx300s_meshes/vx300s_2_shoulder.stl" scale="0.001 0.001 0.001"/>
      </geometry>
    </collision>
    <inertial>
      <origin rpy="0 0 1.5707963267948966" xyz="0.0002592330 -0.0000033552 0.0116129000"/>
      <mass value="0.798614"/>
      <inertia ixx="0.0009388000" ixy="-0.0000000010" ixz="-0.0000000191" iyy="0.0011380000" iyz="0.0000059568" izz="0.0012010000"/>
    </inertial>
  </link>
  <joint name="right/shoulder" type="revolute">
    <axis xyz="0 1 0"/>
    <limit effort="20" lower="-1.8500490071139892" upper="1.2566370614359172" velocity="3.141592653589793"/>
    <origin rpy="0 0 0" xyz="0 0 0.04805"/>
    <parent link="right/vx300s/shoulder_link"/>
    <child link="right/vx300s/upper_arm_link"/>
    <dynamics friction="0.1"/>
  </joint>

  <link name="right/vx300s/upper_arm_link">
    <visual>
      <origin rpy="0 0 1.5707963267948966" xyz="0 0 0"/>
      <geometry>
        <mesh filename="meshes/vx300s_meshes/vx300s_3_upper_arm.stl" scale="0.001 0.001 0.001"/>
      </geometry>
      <material name="interbotix_black"/>
    </visual>
    <collision>
      <origin rpy="0 0 1.5707963267948966" xyz="0 0 0"/>
      <geometry>
        <mesh filename="meshes/vx300s_meshes/vx300s_3_upper_arm.stl" scale="0.001 0.001 0.001"/>
      </geometry>
    </collision>
    <inertial>
      <origin rpy="0 0 1.5707963267948966" xyz="0.0206949000 0.0000000004 0.2264590000"/>
      <mass value="0.792592"/>
      <inertia ixx="0.0089250000" ixy="0.0000000000" ixz="0.0000000000" iyy="0.0089370000" iyz="0.0012010000" izz="0.0009357000"/>
    </inertial>
  </link>
  <joint name="right/elbow" type="revolute">
    <axis xyz="0 1 0"/>
    <limit effort="15" lower="-1.7627825445142729" upper="1.6057029118347832" velocity="3.141592653589793"/>
    <origin rpy="0 0 0" xyz="0.05955 0 0.3"/>
    <parent link="right/vx300s/upper_arm_link"/>
    <child link="right/vx300s/upper_forearm_link"/>
    <dynamics friction="0.1"/>
  </joint>

  <link name="right/vx300s/upper_forearm_link">
    <visual>
      <origin rpy="0 0 0" xyz="0 0 0"/>
      <geometry>
        <mesh filename="meshes/vx300s_meshes/vx300s_4_upper_forearm.stl" scale="0.001 0.001 0.001"/>
      </geometry>
      <material name="interbotix_black"/>
    </visual>
    <collision>
      <origin rpy="0 0 0" xyz="0 0 0"/>
      <geometry>
        <mesh filename="meshes/vx300s_meshes/vx300s_4_upper_forearm.stl" scale="0.001 0.001 0.001"/>
      </geometry>
    </collision>
    <inertial>
      <origin rpy="0 0 0" xyz="0.10723 0 0"/>
      <mass value="0.322228"/>
      <inertia ixx="0.0001524000" ixy="-0.0000188300" ixz="-0.0000084064" iyy="0.0013420000" iyz="0.0000012564" izz="0.0014410000"/>
    </inertial>
  </link>
  <joint name="right/forearm_roll" type="revolute">
    <axis xyz="1 0 0"/>
    <limit effort="2" lower="-3.141582653589793" upper="3.141582653589793" velocity="3.141592653589793"/>
    <origin rpy="0 0 0" xyz="0.2 0 0"/>
    <parent link="right/vx300s/upper_forearm_link"/>
    <child link="right/vx300s/lower_forearm_link"/>
    <dynamics friction="0.1"/>
  </joint>

  <link name="right/vx300s/lower_forearm_link">
    <visual>
      <origin rpy="3.141592653589793 0 0" xyz="0 0 0"/>
      <geometry>
        <mesh filename="meshes/vx300s_meshes/vx300s_5_lower_forearm.stl" scale="0.001 0.001 0.001"/>
      </geometry>
      <material name="interbotix_black"/>
    </visual>
    <collision>
      <origin rpy="3.141592653589793 0 0" xyz="0 0 0"/>
      <geometry>
        <mesh filename="meshes/vx300s_meshes/vx300s_5_lower_forearm.stl" scale="0.001 0.001 0.001"/>
      </geometry>
    </collision>
    <inertial>
      <origin rpy="3.141592653589793 0 0" xyz="0.0513477000 0.0068046200 0"/>
      <mass value="0.214823"/>
      <inertia ixx="0.0001753000" ixy="-0.0000852800" ixz="0" iyy="0.0005269000" iyz="0" izz="0.0005911000"/>
    </inertial>
  </link>
  <joint name="right/wrist_angle" type="revolute">
    <axis xyz="0 1 0"/>
    <limit effort="5" lower="-1.8675022996339325" upper="2.234021442552742" velocity="3.141592653589793"/>
    <origin rpy="0 0.05 0" xyz="0.1 0 0"/>
    <parent link="right/vx300s/lower_forearm_link"/>
    <child link="right/vx300s/wrist_link"/>
    <dynamics friction="0.1"/>
  </joint>

  <link name="right/vx300s/wrist_link">
    <visual>
      <origin rpy="0 0 1.5707963267948966" xyz="0 0 0"/>
      <geometry>
        <mesh filename="meshes/vx300s_meshes/vx300s_6_wrist.stl" scale="0.001 0.001 0.001"/>
      </geometry>
      <material name="interbotix_black"/>
    </visual>
    <collision>
      <origin rpy="0 0 1.5707963267948966" xyz="0 0 0"/>
      <geometry>
        <mesh filename="meshes/vx300s_meshes/vx300s_6_wrist.stl" scale="0.001 0.001 0.001"/>
      </geometry>
    </collision>
    <inertial>
      <origin rpy="0 0 1.5707963267948966" xyz="0.0467430000 -0.0000076652 0.0105650000"/>
      <mass value="0.115395"/>
      <inertia ixx="0.0000463100" ixy="0.0000000195" ixz="0.0000000023" iyy="0.0000451400" iyz="0.0000042002" izz="0.0000527000"/>
    </inertial>
  </link>
  <joint name="right/wrist_rotate" type="revolute">
    <axis xyz="1 0 0"/>
    <limit effort="1" lower="-3.141582653589793" upper="3.141582653589793" velocity="3.141592653589793"/>
    <origin rpy="0 0 0" xyz="0.069744 0 0"/>
    <parent link="right/vx300s/wrist_link"/>
    <child link="right/vx300s/gripper_link"/>
    <dynamics friction="0.1"/>
  </joint>

  <link name="right/vx300s/gripper_link">
    <visual>
      <origin rpy="0 0 1.5707963267948966" xyz="-0.02 0 0"/>
      <geometry>
        <mesh filename="meshes/vx300s_meshes/vx300s_7_gripper.stl" scale="0.001 0.001 0.001"/>
      </geometry>
      <material name="interbotix_black"/>
    </visual>
    <collision>
      <origin rpy="0 0 1.5707963267948966" xyz="-0.02 0 0"/>
      <geometry>
        <mesh filename="meshes/vx300s_meshes/vx300s_7_gripper.stl" scale="0.001 0.001 0.001"/>
      </geometry>
    </collision>
    <inertial>
      <origin rpy="0 0 1.5707963267948966" xyz="0.0230010000 0.0000000000 0.0115230000"/>
      <mass value="0.097666"/>
      <inertia ixx="0.0000326800" ixy="0.0000000000" ixz="0.0000000000" iyy="0.0000243600" iyz="0.0000002785" izz="0.0000211900"/>
    </inertial>
  </link>
  <joint name="right/ee_arm" type="fixed">
    <axis xyz="1 0 0"/>
    <origin rpy="0 0 0" xyz="0.042825 0 0"/>
    <parent link="right/vx300s/gripper_link"/>
    <child link="right/vx300s/ee_arm_link"/>
  </joint>
  <link name="right/vx300s/ee_arm_link">
    <inertial>
      <mass value="0.001"/>
      <inertia ixx="0.0001" ixy="0" ixz="0" iyy="0.0001" iyz="0" izz="0.0001"/>
    </inertial>
  </link>
  <joint name="right/gripper" type="fixed">
    <axis xyz="1 0 0"/>
    <limit effort="1" velocity="3.141592653589793"/>
    <origin rpy="0 0 0" xyz="0.005675 0 0"/>
    <parent link="right/vx300s/ee_arm_link"/>
    <child link="right/vx300s/gripper_prop_link"/>
    <dynamics friction="0.1"/>
  </joint>

  <link name="right/vx300s/gripper_prop_link">
    <visual>
      <origin rpy="0 0 1.5707963267948966" xyz="-0.0685 0 0"/>
      <geometry>
        <mesh filename="meshes/vx300s_meshes/vx300s_8_gripper_prop.stl" scale="0.001 0.001 0.001"/>
      </geometry>
      <material name="interbotix_black"/>
    </visual>
    <collision>
      <origin rpy="0 0 1.5707963267948966" xyz="-0.0685 0 0"/>
      <geometry>
        <mesh filename="meshes/vx300s_meshes/vx300s_8_gripper_prop.stl" scale="0.001 0.001 0.001"/>
      </geometry>
    </collision>
    <inertial>
      <origin rpy="0 0 1.5707963267948966" xyz="0.0023780000 0.0000000285 0.0000000000"/>
      <mass value="0.008009"/>
      <inertia ixx="0.0000020386" ixy="0.0000000000" ixz="0.0000006559" iyy="0.0000042979" iyz="0.0000000000" izz="0.0000023796"/>
    </inertial>
  </link>
  <!-- If the AR tag is being used, then add the AR tag mount -->
  <!-- If the gripper bar is being used, then also add the gripper bar -->
  <joint name="right/gripper_bar" type="fixed">
    <axis xyz="1 0 0"/>
    <origin rpy="0 0 0" xyz="0 0 0"/>
    <parent link="right/vx300s/ee_arm_link"/>
    <child link="right/vx300s/gripper_bar_link"/>
  </joint>
  <link name="right/vx300s/gripper_bar_link">
    <visual>
      <origin rpy="1.57 0 1.57" xyz="0 0 0"/>
      <geometry>
        <mesh filename="meshes/vx300s_meshes/vx300s_9_gripper_bar.stl" scale="1 1 1"/>
      </geometry>
      <material name="interbotix_black"/>
    </visual>
    <collision>
      <origin rpy="1.57 0 1.57" xyz="0 0 0"/>
      <geometry>
        <mesh filename="meshes/vx300s_meshes/vx300s_9_gripper_bar.stl" scale="0.001 0.001 0.001"/>
      </geometry>
    </collision>
    <inertial>
      <origin rpy="1.57 0 1.57" xyz="0.0067940000 -0.0000004272 -0.0007760000"/>
      <mass value="0.150986"/>
      <inertia ixx="0.0000789500" ixy="-0.0000000012" ixz="0.0000001341" iyy="0.0003283000" iyz="0.0000017465" izz="0.0003095000"/>
    </inertial>
  </link>
  <joint name="right/ee_bar" type="fixed">
    <axis xyz="1 0 0"/>
    <origin rpy="0 0 0" xyz="0.025875 0 0"/>
    <parent link="right/vx300s/gripper_bar_link"/>
    <child link="right/vx300s/fingers_link"/>
  </joint>
  <link name="right/vx300s/fingers_link">
    <inertial>
      <mass value="0.001"/>
      <inertia ixx="0.0001" ixy="0" ixz="0" iyy="0.0001" iyz="0" izz="0.0001"/>
    </inertial>
  </link>
  <!-- If the gripper fingers are being used, add those as well -->
  <joint name="right/left_finger" type="prismatic">
    <axis xyz="0 1 0"/>
    <limit effort="5" lower="0.0" upper="0.042" velocity="1"/>
    <origin rpy="0 0 0" xyz="0 0 0"/>
    <parent link="right/vx300s/fingers_link"/>
    <child link="right/vx300s/left_finger_link"/>
    <dynamics friction="0.1"/>
  </joint>

  <joint name="right_arm_elastomer_joint_left" type="fixed">
      <origin rpy="0 -1.57 0" xyz="0.10 0.0012 -0.00"/>
      <parent link="right/vx300s/left_finger_link"/>
      <child link="right_arm_elastomer_left"/>
      <axis xyz="0 0 0"/>
  </joint>
  <link name="right_arm_elastomer_left">         <!-- surface tip of the elastomer  -->
      <visual>
          <origin rpy="0 0 0" xyz="0.0 -0.0 -0.00"/>     <!-- needed when flipping visual mesh in IG  -->
          <geometry>
              <mesh filename="./meshes/aloha_flat_pad.obj"/>
          </geometry>
          <material name="black">
            <color rgba="0.0 0.0 0.0 1.0"/>
          </material>
      </visual>
      <collision>
        <origin rpy="0 0 0" xyz="0.0 -0.0 -0.00"/> 
          <geometry>
              <mesh filename="./meshes/aloha_flat_pad.obj"/>
          </geometry>
          <!-- <sdf resolution="256"/> -->
      </collision>
  </link>

  <link name="right/vx300s/left_finger_link">
    <visual>
      <origin rpy="0 0 1.57 " xyz="0.135 -0.000 0.0125"/>
      <geometry>
        <mesh filename="meshes/vx300s_meshes/gripper.obj" scale="0.001 0.001 0.001"/>
      </geometry>
    </visual>
    <collision>
      <origin rpy="0 0 1.57 " xyz="0.135 -0.000 0.0125"/>
      <geometry>
        <mesh filename="meshes/vx300s_meshes/gripper.obj" scale="0.001 0.001 0.001"/>
      </geometry>
    </collision>
    <inertial>
      <origin rpy="0 0 1.57 " xyz="0.135 -0.000 0.0125"/>
      <mass value="0.034796"/>
      <inertia ixx="0.0000243300" ixy="-0.0000024004" ixz="0.0000000000" iyy="0.0000125500" iyz="0.0000000000" izz="0.0000141700"/>
    </inertial>
  </link>

  <joint name="right/right_finger" type="prismatic">
    <axis xyz="0 1 0"/>
    <limit effort="5" lower="-0.042" upper="-0.0" velocity="1"/>
    <origin rpy="0 0 0" xyz="0 0 0"/>
    <parent link="right/vx300s/fingers_link"/>
    <child link="right/vx300s/right_finger_link"/>
    <dynamics friction="0.1"/>
    <!-- <mimic joint="left_finger" multiplier="-1" offset="0"/> -->
  </joint>

  <link name="right/vx300s/right_finger_link">
    <visual>
      <origin rpy="3.14 0 -1.57 " xyz="0.135 0.000 -0.0125"/>
      <geometry>
        <mesh filename="meshes/vx300s_meshes/gripper.obj" scale="0.001 0.001 0.001"/>
      </geometry>
    </visual>
    <collision>
      <origin rpy="3.14 0 -1.57 " xyz="0.135 0.000 -0.0125"/>
      <geometry>
        <mesh filename="meshes/vx300s_meshes/gripper.obj" scale="0.001 0.001 0.001"/>
      </geometry>
    </collision>
    <inertial>
      <origin rpy="3.14 0 -1.57 " xyz="0.135 0.000 -0.0125"/>
      <mass value="0.034796"/>
      <inertia ixx="0.0000243300" ixy="0.0000024001" ixz="0.0000000000" iyy="0.0000125500" iyz="0.0000000000" izz="0.0000141700"/>
    </inertial>
  </link>

  <joint name="right_arm_elastomer_joint_right" type="fixed">
      <origin rpy="3.14 1.57 0" xyz="0.10 -0.0012 -0.00"/>
      <parent link="right/vx300s/right_finger_link"/>
      <child link="right_arm_elastomer_right"/>
      <axis xyz="0 0 0"/>
  </joint>
  <link name="right_arm_elastomer_right">         <!-- surface tip of the elastomer  -->
      <visual>
          <origin rpy="0 0 0" xyz="0.0 0.0 -0.00"/>     <!-- needed when flipping visual mesh in IG  -->
          <geometry>
              <mesh filename="./meshes/aloha_flat_pad.obj"/>
          </geometry>
          <material name="black">
            <color rgba="0.0 0.0 0.0 1.0"/>
          </material>
      </visual>
      <collision>
        <origin rpy="0 0 0" xyz="0.0 0.0 -0.00"/> 
          <geometry>
              <mesh filename="./meshes/aloha_flat_pad.obj"/>
          </geometry>
          <!-- <sdf resolution="256"/> -->
      </collision>
  </link>

  <joint name="right/ee_gripper" type="fixed">
    <axis xyz="1 0 0"/>
    <origin rpy="0 0 0" xyz="0.0385 0 0"/>
    <parent link="right/vx300s/fingers_link"/>
    <child link="right/vx300s/ee_gripper_link"/>
  </joint>
  <link name="right/vx300s/ee_gripper_link">
    <inertial>
      <mass value="0.001"/>
      <inertia ixx="0.0001" ixy="0" ixz="0" iyy="0.0001" iyz="0" izz="0.0001"/>
    </inertial>
  </link>
 <!-- ++++++++++++++++++++++++++++++++++++++++++right robot end +++++++++++++++++++++++++++++++++++++++++++ -->

</robot>

